In Next.js 15, a subtle bug can occur when using the `app` directory's `fetch` API within a component's `async` function. If the `fetch` call throws an error, and the error isn't properly handled, it might not be caught by a `try...catch` block, potentially leading to a silent failure or unexpected behavior. This can be especially tricky to debug if the error is not explicitly logged or reported by the `fetch` call itself.  This issue is exacerbated by the asynchronous nature of the `app` directory's route handling.  Example:
```javascript
// pages/my-page.js
export default async function MyPage() {
  try {
    const response = await fetch('/api/data');
    if (!response.ok) {
      throw new Error(`HTTP error! status: ${response.status}`);
    }
    const data = await response.json();
    return <div>Data: {JSON.stringify(data)}</div>;
  } catch (error) {
    console.error('Error fetching data:', error);
    return <div>Error loading data.</div>;
  }
}
```
If the `/api/data` route fails unexpectedly (e.g., network error, server-side error), and the error is not caught correctly in the `try...catch`, Next.js may not render the error component or produce any indication of the problem.